<?xml version="1.0" encoding="UTF-8"?>
<!-- Generated by org.testng.reporters.JUnitXMLReporter -->
<testsuite ignored="0" hostname="DESKTOP-RQ6NMQQ" failures="2" tests="3" name="Test" time="9.619" errors="0" timestamp="2024-11-07T22:39:57 IST">
  <testcase classname="testCases.AccountRegistrationTC" name="verify_account_registration" time="2.197"/>
  <testcase classname="testCases.LoginTC" name="validate_login" time="0.009">
    <failure type="java.lang.AssertionError" message="validate_login test failed due to an exception.">
      <![CDATA[java.lang.AssertionError: validate_login test failed due to an exception.
at testCases.LoginTC.validate_login(LoginTC.java:69)
at java.base/java.util.ArrayList.forEach(ArrayList.java:1511)
... Removed 32 stack frames]]>
    </failure>
  </testcase> <!-- validate_login -->
  <testcase classname="testCases.LoginTC" name="validateLogin_Singleton" time="0.001">
    <failure type="java.lang.AssertionError" message="validateLogin_Singleton test failed due to an exception.">
      <![CDATA[java.lang.AssertionError: validateLogin_Singleton test failed due to an exception.
at testCases.LoginTC.validateLogin_Singleton(LoginTC.java:103)
at java.base/java.util.ArrayList.forEach(ArrayList.java:1511)
... Removed 32 stack frames]]>
    </failure>
  </testcase> <!-- validateLogin_Singleton -->
</testsuite> <!-- Test -->
